{
 "cells": [
  {
   "cell_type": "code",
   "execution_count": 4,
   "metadata": {
    "scrolled": false
   },
   "outputs": [
    {
     "name": "stderr",
     "output_type": "stream",
     "text": [
      "Using TensorFlow backend.\n",
      "ERROR:root:Internal Python error in the inspect module.\n",
      "Below is the traceback from this internal error.\n",
      "\n",
      "ERROR:root:Internal Python error in the inspect module.\n",
      "Below is the traceback from this internal error.\n",
      "\n"
     ]
    },
    {
     "name": "stdout",
     "output_type": "stream",
     "text": [
      "Traceback (most recent call last):\n",
      "  File \"C:\\Users\\pcstorm\\AppData\\Roaming\\Python\\Python36\\site-packages\\tensorflow_core\\python\\pywrap_tensorflow.py\", line 58, in <module>\n",
      "    from tensorflow.python.pywrap_tensorflow_internal import *\n",
      "  File \"C:\\Users\\pcstorm\\AppData\\Roaming\\Python\\Python36\\site-packages\\tensorflow_core\\python\\pywrap_tensorflow_internal.py\", line 28, in <module>\n",
      "    _pywrap_tensorflow_internal = swig_import_helper()\n",
      "  File \"C:\\Users\\pcstorm\\AppData\\Roaming\\Python\\Python36\\site-packages\\tensorflow_core\\python\\pywrap_tensorflow_internal.py\", line 24, in swig_import_helper\n",
      "    _mod = imp.load_module('_pywrap_tensorflow_internal', fp, pathname, description)\n",
      "  File \"c:\\users\\pcstorm\\appdata\\local\\programs\\python\\python36\\lib\\imp.py\", line 243, in load_module\n",
      "    return load_dynamic(name, filename, file)\n",
      "  File \"c:\\users\\pcstorm\\appdata\\local\\programs\\python\\python36\\lib\\imp.py\", line 343, in load_dynamic\n",
      "    return _load(spec)\n",
      "ImportError: DLL load failed: The specified module could not be found.\n",
      "\n",
      "During handling of the above exception, another exception occurred:\n",
      "\n",
      "Traceback (most recent call last):\n",
      "  File \"c:\\users\\pcstorm\\appdata\\local\\programs\\python\\python36\\lib\\site-packages\\IPython\\core\\interactiveshell.py\", line 3326, in run_code\n",
      "    exec(code_obj, self.user_global_ns, self.user_ns)\n",
      "  File \"<ipython-input-4-452e4478b1f2>\", line 1, in <module>\n",
      "    from imageai.Detection import ObjectDetection\n",
      "  File \"c:\\users\\pcstorm\\appdata\\local\\programs\\python\\python36\\lib\\site-packages\\imageai\\Detection\\__init__.py\", line 2, in <module>\n",
      "    from imageai.Detection.keras_retinanet.models.resnet import resnet50_retinanet\n",
      "  File \"c:\\users\\pcstorm\\appdata\\local\\programs\\python\\python36\\lib\\site-packages\\imageai\\Detection\\keras_retinanet\\models\\resnet.py\", line 19, in <module>\n",
      "    import keras\n",
      "  File \"c:\\users\\pcstorm\\appdata\\local\\programs\\python\\python36\\lib\\site-packages\\keras\\__init__.py\", line 3, in <module>\n",
      "    from . import utils\n",
      "  File \"c:\\users\\pcstorm\\appdata\\local\\programs\\python\\python36\\lib\\site-packages\\keras\\utils\\__init__.py\", line 6, in <module>\n",
      "    from . import conv_utils\n",
      "  File \"c:\\users\\pcstorm\\appdata\\local\\programs\\python\\python36\\lib\\site-packages\\keras\\utils\\conv_utils.py\", line 9, in <module>\n",
      "    from .. import backend as K\n",
      "  File \"c:\\users\\pcstorm\\appdata\\local\\programs\\python\\python36\\lib\\site-packages\\keras\\backend\\__init__.py\", line 89, in <module>\n",
      "    from .tensorflow_backend import *\n",
      "  File \"c:\\users\\pcstorm\\appdata\\local\\programs\\python\\python36\\lib\\site-packages\\keras\\backend\\tensorflow_backend.py\", line 6, in <module>\n",
      "    from tensorflow.python.framework import ops as tf_ops\n",
      "  File \"C:\\Users\\pcstorm\\AppData\\Roaming\\Python\\Python36\\site-packages\\tensorflow_core\\python\\framework\\ops.py\", line 32, in <module>\n",
      "    from tensorflow.core.framework import attr_value_pb2\n",
      "  File \"C:\\Users\\pcstorm\\AppData\\Roaming\\Python\\Python36\\site-packages\\tensorflow\\__init__.py\", line 50, in __getattr__\n",
      "    module = self._load()\n",
      "  File \"C:\\Users\\pcstorm\\AppData\\Roaming\\Python\\Python36\\site-packages\\tensorflow\\__init__.py\", line 44, in _load\n",
      "    module = _importlib.import_module(self.__name__)\n",
      "  File \"c:\\users\\pcstorm\\appdata\\local\\programs\\python\\python36\\lib\\importlib\\__init__.py\", line 126, in import_module\n",
      "    return _bootstrap._gcd_import(name[level:], package, level)\n",
      "  File \"C:\\Users\\pcstorm\\AppData\\Roaming\\Python\\Python36\\site-packages\\tensorflow_core\\__init__.py\", line 42, in <module>\n",
      "    from . _api.v2 import audio\n",
      "  File \"C:\\Users\\pcstorm\\AppData\\Roaming\\Python\\Python36\\site-packages\\tensorflow_core\\_api\\v2\\audio\\__init__.py\", line 10, in <module>\n",
      "    from tensorflow.python.ops.gen_audio_ops import decode_wav\n",
      "  File \"C:\\Users\\pcstorm\\AppData\\Roaming\\Python\\Python36\\site-packages\\tensorflow_core\\python\\ops\\gen_audio_ops.py\", line 9, in <module>\n",
      "    from tensorflow.python import pywrap_tensorflow as _pywrap_tensorflow\n",
      "  File \"C:\\Users\\pcstorm\\AppData\\Roaming\\Python\\Python36\\site-packages\\tensorflow\\__init__.py\", line 50, in __getattr__\n",
      "    module = self._load()\n",
      "  File \"C:\\Users\\pcstorm\\AppData\\Roaming\\Python\\Python36\\site-packages\\tensorflow\\__init__.py\", line 44, in _load\n",
      "    module = _importlib.import_module(self.__name__)\n",
      "  File \"c:\\users\\pcstorm\\appdata\\local\\programs\\python\\python36\\lib\\importlib\\__init__.py\", line 126, in import_module\n",
      "    return _bootstrap._gcd_import(name[level:], package, level)\n",
      "  File \"C:\\Users\\pcstorm\\AppData\\Roaming\\Python\\Python36\\site-packages\\tensorflow_core\\python\\__init__.py\", line 49, in <module>\n",
      "    from tensorflow.python import pywrap_tensorflow\n",
      "  File \"C:\\Users\\pcstorm\\AppData\\Roaming\\Python\\Python36\\site-packages\\tensorflow_core\\python\\pywrap_tensorflow.py\", line 74, in <module>\n",
      "    raise ImportError(msg)\n",
      "ImportError: Traceback (most recent call last):\n",
      "  File \"C:\\Users\\pcstorm\\AppData\\Roaming\\Python\\Python36\\site-packages\\tensorflow_core\\python\\pywrap_tensorflow.py\", line 58, in <module>\n",
      "    from tensorflow.python.pywrap_tensorflow_internal import *\n",
      "  File \"C:\\Users\\pcstorm\\AppData\\Roaming\\Python\\Python36\\site-packages\\tensorflow_core\\python\\pywrap_tensorflow_internal.py\", line 28, in <module>\n",
      "    _pywrap_tensorflow_internal = swig_import_helper()\n",
      "  File \"C:\\Users\\pcstorm\\AppData\\Roaming\\Python\\Python36\\site-packages\\tensorflow_core\\python\\pywrap_tensorflow_internal.py\", line 24, in swig_import_helper\n",
      "    _mod = imp.load_module('_pywrap_tensorflow_internal', fp, pathname, description)\n",
      "  File \"c:\\users\\pcstorm\\appdata\\local\\programs\\python\\python36\\lib\\imp.py\", line 243, in load_module\n",
      "    return load_dynamic(name, filename, file)\n",
      "  File \"c:\\users\\pcstorm\\appdata\\local\\programs\\python\\python36\\lib\\imp.py\", line 343, in load_dynamic\n",
      "    return _load(spec)\n",
      "ImportError: DLL load failed: The specified module could not be found.\n",
      "\n",
      "\n",
      "Failed to load the native TensorFlow runtime.\n",
      "\n",
      "See https://www.tensorflow.org/install/errors\n",
      "\n",
      "for some common reasons and solutions.  Include the entire stack trace\n",
      "above this error message when asking for help.\n",
      "\n",
      "During handling of the above exception, another exception occurred:\n",
      "\n",
      "Traceback (most recent call last):\n",
      "  File \"c:\\users\\pcstorm\\appdata\\local\\programs\\python\\python36\\lib\\site-packages\\IPython\\core\\interactiveshell.py\", line 2040, in showtraceback\n",
      "    stb = value._render_traceback_()\n",
      "AttributeError: 'ImportError' object has no attribute '_render_traceback_'\n",
      "\n",
      "During handling of the above exception, another exception occurred:\n",
      "\n",
      "Traceback (most recent call last):\n",
      "  File \"C:\\Users\\pcstorm\\AppData\\Roaming\\Python\\Python36\\site-packages\\tensorflow_core\\python\\pywrap_tensorflow.py\", line 58, in <module>\n",
      "    from tensorflow.python.pywrap_tensorflow_internal import *\n",
      "  File \"C:\\Users\\pcstorm\\AppData\\Roaming\\Python\\Python36\\site-packages\\tensorflow_core\\python\\pywrap_tensorflow_internal.py\", line 28, in <module>\n",
      "    _pywrap_tensorflow_internal = swig_import_helper()\n",
      "  File \"C:\\Users\\pcstorm\\AppData\\Roaming\\Python\\Python36\\site-packages\\tensorflow_core\\python\\pywrap_tensorflow_internal.py\", line 24, in swig_import_helper\n",
      "    _mod = imp.load_module('_pywrap_tensorflow_internal', fp, pathname, description)\n",
      "  File \"c:\\users\\pcstorm\\appdata\\local\\programs\\python\\python36\\lib\\imp.py\", line 243, in load_module\n",
      "    return load_dynamic(name, filename, file)\n",
      "  File \"c:\\users\\pcstorm\\appdata\\local\\programs\\python\\python36\\lib\\imp.py\", line 343, in load_dynamic\n",
      "    return _load(spec)\n",
      "ImportError: DLL load failed: The specified module could not be found.\n",
      "\n",
      "During handling of the above exception, another exception occurred:\n",
      "\n",
      "Traceback (most recent call last):\n",
      "  File \"c:\\users\\pcstorm\\appdata\\local\\programs\\python\\python36\\lib\\site-packages\\IPython\\core\\ultratb.py\", line 1101, in get_records\n",
      "    return _fixed_getinnerframes(etb, number_of_lines_of_context, tb_offset)\n",
      "  File \"c:\\users\\pcstorm\\appdata\\local\\programs\\python\\python36\\lib\\site-packages\\IPython\\core\\ultratb.py\", line 319, in wrapped\n",
      "    return f(*args, **kwargs)\n",
      "  File \"c:\\users\\pcstorm\\appdata\\local\\programs\\python\\python36\\lib\\site-packages\\IPython\\core\\ultratb.py\", line 353, in _fixed_getinnerframes\n",
      "    records = fix_frame_records_filenames(inspect.getinnerframes(etb, context))\n",
      "  File \"c:\\users\\pcstorm\\appdata\\local\\programs\\python\\python36\\lib\\inspect.py\", line 1483, in getinnerframes\n",
      "    frameinfo = (tb.tb_frame,) + getframeinfo(tb, context)\n",
      "  File \"c:\\users\\pcstorm\\appdata\\local\\programs\\python\\python36\\lib\\inspect.py\", line 1441, in getframeinfo\n",
      "    filename = getsourcefile(frame) or getfile(frame)\n",
      "  File \"c:\\users\\pcstorm\\appdata\\local\\programs\\python\\python36\\lib\\inspect.py\", line 696, in getsourcefile\n",
      "    if getattr(getmodule(object, filename), '__loader__', None) is not None:\n",
      "  File \"c:\\users\\pcstorm\\appdata\\local\\programs\\python\\python36\\lib\\inspect.py\", line 733, in getmodule\n",
      "    if ismodule(module) and hasattr(module, '__file__'):\n",
      "  File \"C:\\Users\\pcstorm\\AppData\\Roaming\\Python\\Python36\\site-packages\\tensorflow\\__init__.py\", line 50, in __getattr__\n",
      "    module = self._load()\n",
      "  File \"C:\\Users\\pcstorm\\AppData\\Roaming\\Python\\Python36\\site-packages\\tensorflow\\__init__.py\", line 44, in _load\n",
      "    module = _importlib.import_module(self.__name__)\n",
      "  File \"c:\\users\\pcstorm\\appdata\\local\\programs\\python\\python36\\lib\\importlib\\__init__.py\", line 126, in import_module\n",
      "    return _bootstrap._gcd_import(name[level:], package, level)\n",
      "  File \"<frozen importlib._bootstrap>\", line 994, in _gcd_import\n",
      "  File \"<frozen importlib._bootstrap>\", line 971, in _find_and_load\n",
      "  File \"<frozen importlib._bootstrap>\", line 941, in _find_and_load_unlocked\n",
      "  File \"<frozen importlib._bootstrap>\", line 219, in _call_with_frames_removed\n",
      "  File \"<frozen importlib._bootstrap>\", line 994, in _gcd_import\n",
      "  File \"<frozen importlib._bootstrap>\", line 971, in _find_and_load\n",
      "  File \"<frozen importlib._bootstrap>\", line 955, in _find_and_load_unlocked\n",
      "  File \"<frozen importlib._bootstrap>\", line 665, in _load_unlocked\n",
      "  File \"<frozen importlib._bootstrap_external>\", line 678, in exec_module\n",
      "  File \"<frozen importlib._bootstrap>\", line 219, in _call_with_frames_removed\n",
      "  File \"C:\\Users\\pcstorm\\AppData\\Roaming\\Python\\Python36\\site-packages\\tensorflow_core\\__init__.py\", line 42, in <module>\n",
      "    from . _api.v2 import audio\n",
      "  File \"C:\\Users\\pcstorm\\AppData\\Roaming\\Python\\Python36\\site-packages\\tensorflow_core\\_api\\v2\\audio\\__init__.py\", line 10, in <module>\n",
      "    from tensorflow.python.ops.gen_audio_ops import decode_wav\n",
      "  File \"C:\\Users\\pcstorm\\AppData\\Roaming\\Python\\Python36\\site-packages\\tensorflow_core\\python\\ops\\gen_audio_ops.py\", line 9, in <module>\n",
      "    from tensorflow.python import pywrap_tensorflow as _pywrap_tensorflow\n",
      "  File \"C:\\Users\\pcstorm\\AppData\\Roaming\\Python\\Python36\\site-packages\\tensorflow\\__init__.py\", line 50, in __getattr__\n",
      "    module = self._load()\n",
      "  File \"C:\\Users\\pcstorm\\AppData\\Roaming\\Python\\Python36\\site-packages\\tensorflow\\__init__.py\", line 44, in _load\n",
      "    module = _importlib.import_module(self.__name__)\n",
      "  File \"c:\\users\\pcstorm\\appdata\\local\\programs\\python\\python36\\lib\\importlib\\__init__.py\", line 126, in import_module\n",
      "    return _bootstrap._gcd_import(name[level:], package, level)\n",
      "  File \"C:\\Users\\pcstorm\\AppData\\Roaming\\Python\\Python36\\site-packages\\tensorflow_core\\python\\__init__.py\", line 49, in <module>\n",
      "    from tensorflow.python import pywrap_tensorflow\n",
      "  File \"C:\\Users\\pcstorm\\AppData\\Roaming\\Python\\Python36\\site-packages\\tensorflow_core\\python\\pywrap_tensorflow.py\", line 74, in <module>\n",
      "    raise ImportError(msg)\n",
      "ImportError: Traceback (most recent call last):\n",
      "  File \"C:\\Users\\pcstorm\\AppData\\Roaming\\Python\\Python36\\site-packages\\tensorflow_core\\python\\pywrap_tensorflow.py\", line 58, in <module>\n",
      "    from tensorflow.python.pywrap_tensorflow_internal import *\n",
      "  File \"C:\\Users\\pcstorm\\AppData\\Roaming\\Python\\Python36\\site-packages\\tensorflow_core\\python\\pywrap_tensorflow_internal.py\", line 28, in <module>\n",
      "    _pywrap_tensorflow_internal = swig_import_helper()\n",
      "  File \"C:\\Users\\pcstorm\\AppData\\Roaming\\Python\\Python36\\site-packages\\tensorflow_core\\python\\pywrap_tensorflow_internal.py\", line 24, in swig_import_helper\n",
      "    _mod = imp.load_module('_pywrap_tensorflow_internal', fp, pathname, description)\n",
      "  File \"c:\\users\\pcstorm\\appdata\\local\\programs\\python\\python36\\lib\\imp.py\", line 243, in load_module\n",
      "    return load_dynamic(name, filename, file)\n",
      "  File \"c:\\users\\pcstorm\\appdata\\local\\programs\\python\\python36\\lib\\imp.py\", line 343, in load_dynamic\n",
      "    return _load(spec)\n",
      "ImportError: DLL load failed: The specified module could not be found.\n",
      "\n",
      "During handling of the above exception, another exception occurred:\n",
      "\n",
      "Traceback (most recent call last):\n",
      "  File \"c:\\users\\pcstorm\\appdata\\local\\programs\\python\\python36\\lib\\site-packages\\IPython\\core\\interactiveshell.py\", line 3326, in run_code\n",
      "    exec(code_obj, self.user_global_ns, self.user_ns)\n",
      "  File \"<ipython-input-4-452e4478b1f2>\", line 1, in <module>\n",
      "    from imageai.Detection import ObjectDetection\n",
      "  File \"c:\\users\\pcstorm\\appdata\\local\\programs\\python\\python36\\lib\\site-packages\\imageai\\Detection\\__init__.py\", line 2, in <module>\n",
      "    from imageai.Detection.keras_retinanet.models.resnet import resnet50_retinanet\n",
      "  File \"c:\\users\\pcstorm\\appdata\\local\\programs\\python\\python36\\lib\\site-packages\\imageai\\Detection\\keras_retinanet\\models\\resnet.py\", line 19, in <module>\n",
      "    import keras\n",
      "  File \"c:\\users\\pcstorm\\appdata\\local\\programs\\python\\python36\\lib\\site-packages\\keras\\__init__.py\", line 3, in <module>\n",
      "    from . import utils\n",
      "  File \"c:\\users\\pcstorm\\appdata\\local\\programs\\python\\python36\\lib\\site-packages\\keras\\utils\\__init__.py\", line 6, in <module>\n",
      "    from . import conv_utils\n",
      "  File \"c:\\users\\pcstorm\\appdata\\local\\programs\\python\\python36\\lib\\site-packages\\keras\\utils\\conv_utils.py\", line 9, in <module>\n",
      "    from .. import backend as K\n",
      "  File \"c:\\users\\pcstorm\\appdata\\local\\programs\\python\\python36\\lib\\site-packages\\keras\\backend\\__init__.py\", line 89, in <module>\n",
      "    from .tensorflow_backend import *\n",
      "  File \"c:\\users\\pcstorm\\appdata\\local\\programs\\python\\python36\\lib\\site-packages\\keras\\backend\\tensorflow_backend.py\", line 6, in <module>\n",
      "    from tensorflow.python.framework import ops as tf_ops\n",
      "  File \"C:\\Users\\pcstorm\\AppData\\Roaming\\Python\\Python36\\site-packages\\tensorflow_core\\python\\framework\\ops.py\", line 32, in <module>\n",
      "    from tensorflow.core.framework import attr_value_pb2\n",
      "  File \"C:\\Users\\pcstorm\\AppData\\Roaming\\Python\\Python36\\site-packages\\tensorflow\\__init__.py\", line 50, in __getattr__\n",
      "    module = self._load()\n",
      "  File \"C:\\Users\\pcstorm\\AppData\\Roaming\\Python\\Python36\\site-packages\\tensorflow\\__init__.py\", line 44, in _load\n",
      "    module = _importlib.import_module(self.__name__)\n",
      "  File \"c:\\users\\pcstorm\\appdata\\local\\programs\\python\\python36\\lib\\importlib\\__init__.py\", line 126, in import_module\n",
      "    return _bootstrap._gcd_import(name[level:], package, level)\n",
      "  File \"C:\\Users\\pcstorm\\AppData\\Roaming\\Python\\Python36\\site-packages\\tensorflow_core\\__init__.py\", line 42, in <module>\n",
      "    from . _api.v2 import audio\n",
      "  File \"C:\\Users\\pcstorm\\AppData\\Roaming\\Python\\Python36\\site-packages\\tensorflow_core\\_api\\v2\\audio\\__init__.py\", line 10, in <module>\n",
      "    from tensorflow.python.ops.gen_audio_ops import decode_wav\n",
      "  File \"C:\\Users\\pcstorm\\AppData\\Roaming\\Python\\Python36\\site-packages\\tensorflow_core\\python\\ops\\gen_audio_ops.py\", line 9, in <module>\n",
      "    from tensorflow.python import pywrap_tensorflow as _pywrap_tensorflow\n",
      "  File \"C:\\Users\\pcstorm\\AppData\\Roaming\\Python\\Python36\\site-packages\\tensorflow\\__init__.py\", line 50, in __getattr__\n",
      "    module = self._load()\n",
      "  File \"C:\\Users\\pcstorm\\AppData\\Roaming\\Python\\Python36\\site-packages\\tensorflow\\__init__.py\", line 44, in _load\n",
      "    module = _importlib.import_module(self.__name__)\n",
      "  File \"c:\\users\\pcstorm\\appdata\\local\\programs\\python\\python36\\lib\\importlib\\__init__.py\", line 126, in import_module\n",
      "    return _bootstrap._gcd_import(name[level:], package, level)\n",
      "  File \"C:\\Users\\pcstorm\\AppData\\Roaming\\Python\\Python36\\site-packages\\tensorflow_core\\python\\__init__.py\", line 49, in <module>\n",
      "    from tensorflow.python import pywrap_tensorflow\n",
      "  File \"C:\\Users\\pcstorm\\AppData\\Roaming\\Python\\Python36\\site-packages\\tensorflow_core\\python\\pywrap_tensorflow.py\", line 74, in <module>\n",
      "    raise ImportError(msg)\n",
      "ImportError: Traceback (most recent call last):\n",
      "  File \"C:\\Users\\pcstorm\\AppData\\Roaming\\Python\\Python36\\site-packages\\tensorflow_core\\python\\pywrap_tensorflow.py\", line 58, in <module>\n",
      "    from tensorflow.python.pywrap_tensorflow_internal import *\n",
      "  File \"C:\\Users\\pcstorm\\AppData\\Roaming\\Python\\Python36\\site-packages\\tensorflow_core\\python\\pywrap_tensorflow_internal.py\", line 28, in <module>\n",
      "    _pywrap_tensorflow_internal = swig_import_helper()\n",
      "  File \"C:\\Users\\pcstorm\\AppData\\Roaming\\Python\\Python36\\site-packages\\tensorflow_core\\python\\pywrap_tensorflow_internal.py\", line 24, in swig_import_helper\n",
      "    _mod = imp.load_module('_pywrap_tensorflow_internal', fp, pathname, description)\n",
      "  File \"c:\\users\\pcstorm\\appdata\\local\\programs\\python\\python36\\lib\\imp.py\", line 243, in load_module\n",
      "    return load_dynamic(name, filename, file)\n",
      "  File \"c:\\users\\pcstorm\\appdata\\local\\programs\\python\\python36\\lib\\imp.py\", line 343, in load_dynamic\n",
      "    return _load(spec)\n",
      "ImportError: DLL load failed: The specified module could not be found.\n",
      "\n",
      "\n",
      "Failed to load the native TensorFlow runtime.\n",
      "\n",
      "See https://www.tensorflow.org/install/errors\n",
      "\n",
      "for some common reasons and solutions.  Include the entire stack trace\n",
      "above this error message when asking for help.\n",
      "\n",
      "During handling of the above exception, another exception occurred:\n",
      "\n",
      "Traceback (most recent call last):\n",
      "  File \"c:\\users\\pcstorm\\appdata\\local\\programs\\python\\python36\\lib\\site-packages\\IPython\\core\\interactiveshell.py\", line 2040, in showtraceback\n",
      "    stb = value._render_traceback_()\n",
      "AttributeError: 'ImportError' object has no attribute '_render_traceback_'\n",
      "\n",
      "During handling of the above exception, another exception occurred:\n",
      "\n",
      "Traceback (most recent call last):\n",
      "  File \"C:\\Users\\pcstorm\\AppData\\Roaming\\Python\\Python36\\site-packages\\tensorflow_core\\python\\pywrap_tensorflow.py\", line 58, in <module>\n",
      "    from tensorflow.python.pywrap_tensorflow_internal import *\n",
      "  File \"C:\\Users\\pcstorm\\AppData\\Roaming\\Python\\Python36\\site-packages\\tensorflow_core\\python\\pywrap_tensorflow_internal.py\", line 28, in <module>\n",
      "    _pywrap_tensorflow_internal = swig_import_helper()\n",
      "  File \"C:\\Users\\pcstorm\\AppData\\Roaming\\Python\\Python36\\site-packages\\tensorflow_core\\python\\pywrap_tensorflow_internal.py\", line 24, in swig_import_helper\n",
      "    _mod = imp.load_module('_pywrap_tensorflow_internal', fp, pathname, description)\n",
      "  File \"c:\\users\\pcstorm\\appdata\\local\\programs\\python\\python36\\lib\\imp.py\", line 243, in load_module\n",
      "    return load_dynamic(name, filename, file)\n",
      "  File \"c:\\users\\pcstorm\\appdata\\local\\programs\\python\\python36\\lib\\imp.py\", line 343, in load_dynamic\n",
      "    return _load(spec)\n",
      "ImportError: DLL load failed: The specified module could not be found.\n",
      "\n",
      "\n",
      "Failed to load the native TensorFlow runtime.\n",
      "\n",
      "See https://www.tensorflow.org/install/errors\n",
      "\n",
      "for some common reasons and solutions.  Include the entire stack trace\n",
      "above this error message when asking for help.\n",
      "Traceback (most recent call last):\n",
      "  File \"C:\\Users\\pcstorm\\AppData\\Roaming\\Python\\Python36\\site-packages\\tensorflow_core\\python\\pywrap_tensorflow.py\", line 58, in <module>\n",
      "    from tensorflow.python.pywrap_tensorflow_internal import *\n",
      "  File \"C:\\Users\\pcstorm\\AppData\\Roaming\\Python\\Python36\\site-packages\\tensorflow_core\\python\\pywrap_tensorflow_internal.py\", line 28, in <module>\n",
      "    _pywrap_tensorflow_internal = swig_import_helper()\n",
      "  File \"C:\\Users\\pcstorm\\AppData\\Roaming\\Python\\Python36\\site-packages\\tensorflow_core\\python\\pywrap_tensorflow_internal.py\", line 24, in swig_import_helper\n",
      "    _mod = imp.load_module('_pywrap_tensorflow_internal', fp, pathname, description)\n",
      "  File \"c:\\users\\pcstorm\\appdata\\local\\programs\\python\\python36\\lib\\imp.py\", line 243, in load_module\n",
      "    return load_dynamic(name, filename, file)\n",
      "  File \"c:\\users\\pcstorm\\appdata\\local\\programs\\python\\python36\\lib\\imp.py\", line 343, in load_dynamic\n",
      "    return _load(spec)\n",
      "ImportError: DLL load failed: The specified module could not be found.\n",
      "\n",
      "During handling of the above exception, another exception occurred:\n",
      "\n",
      "Traceback (most recent call last):\n",
      "  File \"c:\\users\\pcstorm\\appdata\\local\\programs\\python\\python36\\lib\\site-packages\\IPython\\core\\interactiveshell.py\", line 3326, in run_code\n",
      "    exec(code_obj, self.user_global_ns, self.user_ns)\n",
      "  File \"<ipython-input-4-452e4478b1f2>\", line 1, in <module>\n",
      "    from imageai.Detection import ObjectDetection\n",
      "  File \"c:\\users\\pcstorm\\appdata\\local\\programs\\python\\python36\\lib\\site-packages\\imageai\\Detection\\__init__.py\", line 2, in <module>\n",
      "    from imageai.Detection.keras_retinanet.models.resnet import resnet50_retinanet\n",
      "  File \"c:\\users\\pcstorm\\appdata\\local\\programs\\python\\python36\\lib\\site-packages\\imageai\\Detection\\keras_retinanet\\models\\resnet.py\", line 19, in <module>\n",
      "    import keras\n",
      "  File \"c:\\users\\pcstorm\\appdata\\local\\programs\\python\\python36\\lib\\site-packages\\keras\\__init__.py\", line 3, in <module>\n",
      "    from . import utils\n",
      "  File \"c:\\users\\pcstorm\\appdata\\local\\programs\\python\\python36\\lib\\site-packages\\keras\\utils\\__init__.py\", line 6, in <module>\n",
      "    from . import conv_utils\n",
      "  File \"c:\\users\\pcstorm\\appdata\\local\\programs\\python\\python36\\lib\\site-packages\\keras\\utils\\conv_utils.py\", line 9, in <module>\n",
      "    from .. import backend as K\n",
      "  File \"c:\\users\\pcstorm\\appdata\\local\\programs\\python\\python36\\lib\\site-packages\\keras\\backend\\__init__.py\", line 89, in <module>\n",
      "    from .tensorflow_backend import *\n",
      "  File \"c:\\users\\pcstorm\\appdata\\local\\programs\\python\\python36\\lib\\site-packages\\keras\\backend\\tensorflow_backend.py\", line 6, in <module>\n",
      "    from tensorflow.python.framework import ops as tf_ops\n",
      "  File \"C:\\Users\\pcstorm\\AppData\\Roaming\\Python\\Python36\\site-packages\\tensorflow_core\\python\\framework\\ops.py\", line 32, in <module>\n",
      "    from tensorflow.core.framework import attr_value_pb2\n",
      "  File \"C:\\Users\\pcstorm\\AppData\\Roaming\\Python\\Python36\\site-packages\\tensorflow\\__init__.py\", line 50, in __getattr__\n",
      "    module = self._load()\n",
      "  File \"C:\\Users\\pcstorm\\AppData\\Roaming\\Python\\Python36\\site-packages\\tensorflow\\__init__.py\", line 44, in _load\n",
      "    module = _importlib.import_module(self.__name__)\n",
      "  File \"c:\\users\\pcstorm\\appdata\\local\\programs\\python\\python36\\lib\\importlib\\__init__.py\", line 126, in import_module\n",
      "    return _bootstrap._gcd_import(name[level:], package, level)\n",
      "  File \"C:\\Users\\pcstorm\\AppData\\Roaming\\Python\\Python36\\site-packages\\tensorflow_core\\__init__.py\", line 42, in <module>\n",
      "    from . _api.v2 import audio\n",
      "  File \"C:\\Users\\pcstorm\\AppData\\Roaming\\Python\\Python36\\site-packages\\tensorflow_core\\_api\\v2\\audio\\__init__.py\", line 10, in <module>\n",
      "    from tensorflow.python.ops.gen_audio_ops import decode_wav\n",
      "  File \"C:\\Users\\pcstorm\\AppData\\Roaming\\Python\\Python36\\site-packages\\tensorflow_core\\python\\ops\\gen_audio_ops.py\", line 9, in <module>\n",
      "    from tensorflow.python import pywrap_tensorflow as _pywrap_tensorflow\n",
      "  File \"C:\\Users\\pcstorm\\AppData\\Roaming\\Python\\Python36\\site-packages\\tensorflow\\__init__.py\", line 50, in __getattr__\n",
      "    module = self._load()\n",
      "  File \"C:\\Users\\pcstorm\\AppData\\Roaming\\Python\\Python36\\site-packages\\tensorflow\\__init__.py\", line 44, in _load\n",
      "    module = _importlib.import_module(self.__name__)\n",
      "  File \"c:\\users\\pcstorm\\appdata\\local\\programs\\python\\python36\\lib\\importlib\\__init__.py\", line 126, in import_module\n",
      "    return _bootstrap._gcd_import(name[level:], package, level)\n",
      "  File \"C:\\Users\\pcstorm\\AppData\\Roaming\\Python\\Python36\\site-packages\\tensorflow_core\\python\\__init__.py\", line 49, in <module>\n",
      "    from tensorflow.python import pywrap_tensorflow\n",
      "  File \"C:\\Users\\pcstorm\\AppData\\Roaming\\Python\\Python36\\site-packages\\tensorflow_core\\python\\pywrap_tensorflow.py\", line 74, in <module>\n",
      "    raise ImportError(msg)\n",
      "ImportError: Traceback (most recent call last):\n",
      "  File \"C:\\Users\\pcstorm\\AppData\\Roaming\\Python\\Python36\\site-packages\\tensorflow_core\\python\\pywrap_tensorflow.py\", line 58, in <module>\n",
      "    from tensorflow.python.pywrap_tensorflow_internal import *\n",
      "  File \"C:\\Users\\pcstorm\\AppData\\Roaming\\Python\\Python36\\site-packages\\tensorflow_core\\python\\pywrap_tensorflow_internal.py\", line 28, in <module>\n",
      "    _pywrap_tensorflow_internal = swig_import_helper()\n",
      "  File \"C:\\Users\\pcstorm\\AppData\\Roaming\\Python\\Python36\\site-packages\\tensorflow_core\\python\\pywrap_tensorflow_internal.py\", line 24, in swig_import_helper\n",
      "    _mod = imp.load_module('_pywrap_tensorflow_internal', fp, pathname, description)\n",
      "  File \"c:\\users\\pcstorm\\appdata\\local\\programs\\python\\python36\\lib\\imp.py\", line 243, in load_module\n",
      "    return load_dynamic(name, filename, file)\n",
      "  File \"c:\\users\\pcstorm\\appdata\\local\\programs\\python\\python36\\lib\\imp.py\", line 343, in load_dynamic\n",
      "    return _load(spec)\n",
      "ImportError: DLL load failed: The specified module could not be found.\n",
      "\n",
      "\n",
      "Failed to load the native TensorFlow runtime.\n",
      "\n",
      "See https://www.tensorflow.org/install/errors\n",
      "\n",
      "for some common reasons and solutions.  Include the entire stack trace\n",
      "above this error message when asking for help.\n",
      "\n",
      "During handling of the above exception, another exception occurred:\n",
      "\n",
      "Traceback (most recent call last):\n",
      "  File \"c:\\users\\pcstorm\\appdata\\local\\programs\\python\\python36\\lib\\site-packages\\IPython\\core\\interactiveshell.py\", line 2040, in showtraceback\n",
      "    stb = value._render_traceback_()\n",
      "AttributeError: 'ImportError' object has no attribute '_render_traceback_'\n",
      "\n",
      "During handling of the above exception, another exception occurred:\n",
      "\n",
      "Traceback (most recent call last):\n",
      "  File \"c:\\users\\pcstorm\\appdata\\local\\programs\\python\\python36\\lib\\site-packages\\IPython\\core\\interactiveshell.py\", line 3249, in run_ast_nodes\n",
      "    if (await self.run_code(code, result,  async_=asy)):\n",
      "  File \"c:\\users\\pcstorm\\appdata\\local\\programs\\python\\python36\\lib\\site-packages\\IPython\\core\\interactiveshell.py\", line 3343, in run_code\n",
      "    self.showtraceback(running_compiled_code=True)\n",
      "  File \"c:\\users\\pcstorm\\appdata\\local\\programs\\python\\python36\\lib\\site-packages\\IPython\\core\\interactiveshell.py\", line 2043, in showtraceback\n",
      "    value, tb, tb_offset=tb_offset)\n",
      "  File \"c:\\users\\pcstorm\\appdata\\local\\programs\\python\\python36\\lib\\site-packages\\IPython\\core\\ultratb.py\", line 1385, in structured_traceback\n",
      "    self, etype, value, tb, tb_offset, number_of_lines_of_context)\n",
      "  File \"c:\\users\\pcstorm\\appdata\\local\\programs\\python\\python36\\lib\\site-packages\\IPython\\core\\ultratb.py\", line 1288, in structured_traceback\n",
      "    self, etype, value, tb, tb_offset, number_of_lines_of_context\n",
      "  File \"c:\\users\\pcstorm\\appdata\\local\\programs\\python\\python36\\lib\\site-packages\\IPython\\core\\ultratb.py\", line 1150, in structured_traceback\n",
      "    formatted_exceptions += self.prepare_chained_exception_message(evalue.__cause__)\n",
      "TypeError: must be str, not list\n",
      "\n",
      "During handling of the above exception, another exception occurred:\n",
      "\n",
      "Traceback (most recent call last):\n",
      "  File \"c:\\users\\pcstorm\\appdata\\local\\programs\\python\\python36\\lib\\site-packages\\IPython\\core\\interactiveshell.py\", line 2040, in showtraceback\n",
      "    stb = value._render_traceback_()\n",
      "AttributeError: 'TypeError' object has no attribute '_render_traceback_'\n",
      "\n",
      "During handling of the above exception, another exception occurred:\n",
      "\n",
      "Traceback (most recent call last):\n",
      "  File \"C:\\Users\\pcstorm\\AppData\\Roaming\\Python\\Python36\\site-packages\\tensorflow_core\\python\\pywrap_tensorflow.py\", line 58, in <module>\n",
      "    from tensorflow.python.pywrap_tensorflow_internal import *\n",
      "  File \"C:\\Users\\pcstorm\\AppData\\Roaming\\Python\\Python36\\site-packages\\tensorflow_core\\python\\pywrap_tensorflow_internal.py\", line 28, in <module>\n",
      "    _pywrap_tensorflow_internal = swig_import_helper()\n",
      "  File \"C:\\Users\\pcstorm\\AppData\\Roaming\\Python\\Python36\\site-packages\\tensorflow_core\\python\\pywrap_tensorflow_internal.py\", line 24, in swig_import_helper\n",
      "    _mod = imp.load_module('_pywrap_tensorflow_internal', fp, pathname, description)\n",
      "  File \"c:\\users\\pcstorm\\appdata\\local\\programs\\python\\python36\\lib\\imp.py\", line 243, in load_module\n",
      "    return load_dynamic(name, filename, file)\n",
      "  File \"c:\\users\\pcstorm\\appdata\\local\\programs\\python\\python36\\lib\\imp.py\", line 343, in load_dynamic\n",
      "    return _load(spec)\n",
      "ImportError: DLL load failed: The specified module could not be found.\n",
      "\n",
      "During handling of the above exception, another exception occurred:\n",
      "\n",
      "Traceback (most recent call last):\n",
      "  File \"c:\\users\\pcstorm\\appdata\\local\\programs\\python\\python36\\lib\\site-packages\\IPython\\core\\ultratb.py\", line 1101, in get_records\n",
      "    return _fixed_getinnerframes(etb, number_of_lines_of_context, tb_offset)\n",
      "  File \"c:\\users\\pcstorm\\appdata\\local\\programs\\python\\python36\\lib\\site-packages\\IPython\\core\\ultratb.py\", line 319, in wrapped\n",
      "    return f(*args, **kwargs)\n",
      "  File \"c:\\users\\pcstorm\\appdata\\local\\programs\\python\\python36\\lib\\site-packages\\IPython\\core\\ultratb.py\", line 353, in _fixed_getinnerframes\n",
      "    records = fix_frame_records_filenames(inspect.getinnerframes(etb, context))\n",
      "  File \"c:\\users\\pcstorm\\appdata\\local\\programs\\python\\python36\\lib\\inspect.py\", line 1483, in getinnerframes\n",
      "    frameinfo = (tb.tb_frame,) + getframeinfo(tb, context)\n",
      "  File \"c:\\users\\pcstorm\\appdata\\local\\programs\\python\\python36\\lib\\inspect.py\", line 1441, in getframeinfo\n",
      "    filename = getsourcefile(frame) or getfile(frame)\n",
      "  File \"c:\\users\\pcstorm\\appdata\\local\\programs\\python\\python36\\lib\\inspect.py\", line 696, in getsourcefile\n",
      "    if getattr(getmodule(object, filename), '__loader__', None) is not None:\n",
      "  File \"c:\\users\\pcstorm\\appdata\\local\\programs\\python\\python36\\lib\\inspect.py\", line 733, in getmodule\n",
      "    if ismodule(module) and hasattr(module, '__file__'):\n",
      "  File \"C:\\Users\\pcstorm\\AppData\\Roaming\\Python\\Python36\\site-packages\\tensorflow\\__init__.py\", line 50, in __getattr__\n",
      "    module = self._load()\n",
      "  File \"C:\\Users\\pcstorm\\AppData\\Roaming\\Python\\Python36\\site-packages\\tensorflow\\__init__.py\", line 44, in _load\n",
      "    module = _importlib.import_module(self.__name__)\n",
      "  File \"c:\\users\\pcstorm\\appdata\\local\\programs\\python\\python36\\lib\\importlib\\__init__.py\", line 126, in import_module\n",
      "    return _bootstrap._gcd_import(name[level:], package, level)\n",
      "  File \"<frozen importlib._bootstrap>\", line 994, in _gcd_import\n",
      "  File \"<frozen importlib._bootstrap>\", line 971, in _find_and_load\n",
      "  File \"<frozen importlib._bootstrap>\", line 941, in _find_and_load_unlocked\n",
      "  File \"<frozen importlib._bootstrap>\", line 219, in _call_with_frames_removed\n",
      "  File \"<frozen importlib._bootstrap>\", line 994, in _gcd_import\n",
      "  File \"<frozen importlib._bootstrap>\", line 971, in _find_and_load\n",
      "  File \"<frozen importlib._bootstrap>\", line 955, in _find_and_load_unlocked\n",
      "  File \"<frozen importlib._bootstrap>\", line 665, in _load_unlocked\n",
      "  File \"<frozen importlib._bootstrap_external>\", line 678, in exec_module\n",
      "  File \"<frozen importlib._bootstrap>\", line 219, in _call_with_frames_removed\n",
      "  File \"C:\\Users\\pcstorm\\AppData\\Roaming\\Python\\Python36\\site-packages\\tensorflow_core\\__init__.py\", line 42, in <module>\n",
      "    from . _api.v2 import audio\n",
      "  File \"C:\\Users\\pcstorm\\AppData\\Roaming\\Python\\Python36\\site-packages\\tensorflow_core\\_api\\v2\\audio\\__init__.py\", line 10, in <module>\n",
      "    from tensorflow.python.ops.gen_audio_ops import decode_wav\n",
      "  File \"C:\\Users\\pcstorm\\AppData\\Roaming\\Python\\Python36\\site-packages\\tensorflow_core\\python\\ops\\gen_audio_ops.py\", line 9, in <module>\n",
      "    from tensorflow.python import pywrap_tensorflow as _pywrap_tensorflow\n",
      "  File \"C:\\Users\\pcstorm\\AppData\\Roaming\\Python\\Python36\\site-packages\\tensorflow\\__init__.py\", line 50, in __getattr__\n",
      "    module = self._load()\n",
      "  File \"C:\\Users\\pcstorm\\AppData\\Roaming\\Python\\Python36\\site-packages\\tensorflow\\__init__.py\", line 44, in _load\n",
      "    module = _importlib.import_module(self.__name__)\n",
      "  File \"c:\\users\\pcstorm\\appdata\\local\\programs\\python\\python36\\lib\\importlib\\__init__.py\", line 126, in import_module\n",
      "    return _bootstrap._gcd_import(name[level:], package, level)\n",
      "  File \"C:\\Users\\pcstorm\\AppData\\Roaming\\Python\\Python36\\site-packages\\tensorflow_core\\python\\__init__.py\", line 49, in <module>\n",
      "    from tensorflow.python import pywrap_tensorflow\n",
      "  File \"C:\\Users\\pcstorm\\AppData\\Roaming\\Python\\Python36\\site-packages\\tensorflow_core\\python\\pywrap_tensorflow.py\", line 74, in <module>\n",
      "    raise ImportError(msg)\n",
      "ImportError: Traceback (most recent call last):\n",
      "  File \"C:\\Users\\pcstorm\\AppData\\Roaming\\Python\\Python36\\site-packages\\tensorflow_core\\python\\pywrap_tensorflow.py\", line 58, in <module>\n",
      "    from tensorflow.python.pywrap_tensorflow_internal import *\n",
      "  File \"C:\\Users\\pcstorm\\AppData\\Roaming\\Python\\Python36\\site-packages\\tensorflow_core\\python\\pywrap_tensorflow_internal.py\", line 28, in <module>\n",
      "    _pywrap_tensorflow_internal = swig_import_helper()\n",
      "  File \"C:\\Users\\pcstorm\\AppData\\Roaming\\Python\\Python36\\site-packages\\tensorflow_core\\python\\pywrap_tensorflow_internal.py\", line 24, in swig_import_helper\n",
      "    _mod = imp.load_module('_pywrap_tensorflow_internal', fp, pathname, description)\n",
      "  File \"c:\\users\\pcstorm\\appdata\\local\\programs\\python\\python36\\lib\\imp.py\", line 243, in load_module\n",
      "    return load_dynamic(name, filename, file)\n",
      "  File \"c:\\users\\pcstorm\\appdata\\local\\programs\\python\\python36\\lib\\imp.py\", line 343, in load_dynamic\n",
      "    return _load(spec)\n",
      "ImportError: DLL load failed: The specified module could not be found.\n",
      "\n",
      "During handling of the above exception, another exception occurred:\n",
      "\n",
      "Traceback (most recent call last):\n",
      "  File \"c:\\users\\pcstorm\\appdata\\local\\programs\\python\\python36\\lib\\site-packages\\IPython\\core\\interactiveshell.py\", line 3326, in run_code\n",
      "    exec(code_obj, self.user_global_ns, self.user_ns)\n",
      "  File \"<ipython-input-4-452e4478b1f2>\", line 1, in <module>\n",
      "    from imageai.Detection import ObjectDetection\n",
      "  File \"c:\\users\\pcstorm\\appdata\\local\\programs\\python\\python36\\lib\\site-packages\\imageai\\Detection\\__init__.py\", line 2, in <module>\n",
      "    from imageai.Detection.keras_retinanet.models.resnet import resnet50_retinanet\n",
      "  File \"c:\\users\\pcstorm\\appdata\\local\\programs\\python\\python36\\lib\\site-packages\\imageai\\Detection\\keras_retinanet\\models\\resnet.py\", line 19, in <module>\n",
      "    import keras\n",
      "  File \"c:\\users\\pcstorm\\appdata\\local\\programs\\python\\python36\\lib\\site-packages\\keras\\__init__.py\", line 3, in <module>\n",
      "    from . import utils\n",
      "  File \"c:\\users\\pcstorm\\appdata\\local\\programs\\python\\python36\\lib\\site-packages\\keras\\utils\\__init__.py\", line 6, in <module>\n",
      "    from . import conv_utils\n",
      "  File \"c:\\users\\pcstorm\\appdata\\local\\programs\\python\\python36\\lib\\site-packages\\keras\\utils\\conv_utils.py\", line 9, in <module>\n",
      "    from .. import backend as K\n",
      "  File \"c:\\users\\pcstorm\\appdata\\local\\programs\\python\\python36\\lib\\site-packages\\keras\\backend\\__init__.py\", line 89, in <module>\n",
      "    from .tensorflow_backend import *\n",
      "  File \"c:\\users\\pcstorm\\appdata\\local\\programs\\python\\python36\\lib\\site-packages\\keras\\backend\\tensorflow_backend.py\", line 6, in <module>\n",
      "    from tensorflow.python.framework import ops as tf_ops\n",
      "  File \"C:\\Users\\pcstorm\\AppData\\Roaming\\Python\\Python36\\site-packages\\tensorflow_core\\python\\framework\\ops.py\", line 32, in <module>\n",
      "    from tensorflow.core.framework import attr_value_pb2\n",
      "  File \"C:\\Users\\pcstorm\\AppData\\Roaming\\Python\\Python36\\site-packages\\tensorflow\\__init__.py\", line 50, in __getattr__\n",
      "    module = self._load()\n",
      "  File \"C:\\Users\\pcstorm\\AppData\\Roaming\\Python\\Python36\\site-packages\\tensorflow\\__init__.py\", line 44, in _load\n",
      "    module = _importlib.import_module(self.__name__)\n",
      "  File \"c:\\users\\pcstorm\\appdata\\local\\programs\\python\\python36\\lib\\importlib\\__init__.py\", line 126, in import_module\n",
      "    return _bootstrap._gcd_import(name[level:], package, level)\n",
      "  File \"C:\\Users\\pcstorm\\AppData\\Roaming\\Python\\Python36\\site-packages\\tensorflow_core\\__init__.py\", line 42, in <module>\n",
      "    from . _api.v2 import audio\n",
      "  File \"C:\\Users\\pcstorm\\AppData\\Roaming\\Python\\Python36\\site-packages\\tensorflow_core\\_api\\v2\\audio\\__init__.py\", line 10, in <module>\n",
      "    from tensorflow.python.ops.gen_audio_ops import decode_wav\n",
      "  File \"C:\\Users\\pcstorm\\AppData\\Roaming\\Python\\Python36\\site-packages\\tensorflow_core\\python\\ops\\gen_audio_ops.py\", line 9, in <module>\n",
      "    from tensorflow.python import pywrap_tensorflow as _pywrap_tensorflow\n",
      "  File \"C:\\Users\\pcstorm\\AppData\\Roaming\\Python\\Python36\\site-packages\\tensorflow\\__init__.py\", line 50, in __getattr__\n",
      "    module = self._load()\n",
      "  File \"C:\\Users\\pcstorm\\AppData\\Roaming\\Python\\Python36\\site-packages\\tensorflow\\__init__.py\", line 44, in _load\n",
      "    module = _importlib.import_module(self.__name__)\n",
      "  File \"c:\\users\\pcstorm\\appdata\\local\\programs\\python\\python36\\lib\\importlib\\__init__.py\", line 126, in import_module\n",
      "    return _bootstrap._gcd_import(name[level:], package, level)\n",
      "  File \"C:\\Users\\pcstorm\\AppData\\Roaming\\Python\\Python36\\site-packages\\tensorflow_core\\python\\__init__.py\", line 49, in <module>\n",
      "    from tensorflow.python import pywrap_tensorflow\n",
      "  File \"C:\\Users\\pcstorm\\AppData\\Roaming\\Python\\Python36\\site-packages\\tensorflow_core\\python\\pywrap_tensorflow.py\", line 74, in <module>\n",
      "    raise ImportError(msg)\n",
      "ImportError: Traceback (most recent call last):\n",
      "  File \"C:\\Users\\pcstorm\\AppData\\Roaming\\Python\\Python36\\site-packages\\tensorflow_core\\python\\pywrap_tensorflow.py\", line 58, in <module>\n",
      "    from tensorflow.python.pywrap_tensorflow_internal import *\n",
      "  File \"C:\\Users\\pcstorm\\AppData\\Roaming\\Python\\Python36\\site-packages\\tensorflow_core\\python\\pywrap_tensorflow_internal.py\", line 28, in <module>\n",
      "    _pywrap_tensorflow_internal = swig_import_helper()\n",
      "  File \"C:\\Users\\pcstorm\\AppData\\Roaming\\Python\\Python36\\site-packages\\tensorflow_core\\python\\pywrap_tensorflow_internal.py\", line 24, in swig_import_helper\n",
      "    _mod = imp.load_module('_pywrap_tensorflow_internal', fp, pathname, description)\n",
      "  File \"c:\\users\\pcstorm\\appdata\\local\\programs\\python\\python36\\lib\\imp.py\", line 243, in load_module\n",
      "    return load_dynamic(name, filename, file)\n",
      "  File \"c:\\users\\pcstorm\\appdata\\local\\programs\\python\\python36\\lib\\imp.py\", line 343, in load_dynamic\n",
      "    return _load(spec)\n",
      "ImportError: DLL load failed: The specified module could not be found.\n",
      "\n",
      "\n",
      "Failed to load the native TensorFlow runtime.\n",
      "\n",
      "See https://www.tensorflow.org/install/errors\n",
      "\n",
      "for some common reasons and solutions.  Include the entire stack trace\n",
      "above this error message when asking for help.\n",
      "\n",
      "During handling of the above exception, another exception occurred:\n",
      "\n",
      "Traceback (most recent call last):\n",
      "  File \"c:\\users\\pcstorm\\appdata\\local\\programs\\python\\python36\\lib\\site-packages\\IPython\\core\\interactiveshell.py\", line 2040, in showtraceback\n",
      "    stb = value._render_traceback_()\n",
      "AttributeError: 'ImportError' object has no attribute '_render_traceback_'\n",
      "\n",
      "During handling of the above exception, another exception occurred:\n",
      "\n",
      "Traceback (most recent call last):\n",
      "  File \"c:\\users\\pcstorm\\appdata\\local\\programs\\python\\python36\\lib\\site-packages\\IPython\\core\\interactiveshell.py\", line 3249, in run_ast_nodes\n",
      "    if (await self.run_code(code, result,  async_=asy)):\n",
      "  File \"c:\\users\\pcstorm\\appdata\\local\\programs\\python\\python36\\lib\\site-packages\\IPython\\core\\interactiveshell.py\", line 3343, in run_code\n",
      "    self.showtraceback(running_compiled_code=True)\n",
      "  File \"c:\\users\\pcstorm\\appdata\\local\\programs\\python\\python36\\lib\\site-packages\\IPython\\core\\interactiveshell.py\", line 2043, in showtraceback\n",
      "    value, tb, tb_offset=tb_offset)\n",
      "  File \"c:\\users\\pcstorm\\appdata\\local\\programs\\python\\python36\\lib\\site-packages\\IPython\\core\\ultratb.py\", line 1385, in structured_traceback\n",
      "    self, etype, value, tb, tb_offset, number_of_lines_of_context)\n",
      "  File \"c:\\users\\pcstorm\\appdata\\local\\programs\\python\\python36\\lib\\site-packages\\IPython\\core\\ultratb.py\", line 1288, in structured_traceback\n",
      "    self, etype, value, tb, tb_offset, number_of_lines_of_context\n",
      "  File \"c:\\users\\pcstorm\\appdata\\local\\programs\\python\\python36\\lib\\site-packages\\IPython\\core\\ultratb.py\", line 1150, in structured_traceback\n",
      "    formatted_exceptions += self.prepare_chained_exception_message(evalue.__cause__)\n",
      "TypeError: must be str, not list\n",
      "\n",
      "During handling of the above exception, another exception occurred:\n",
      "\n",
      "Traceback (most recent call last):\n",
      "  File \"c:\\users\\pcstorm\\appdata\\local\\programs\\python\\python36\\lib\\site-packages\\IPython\\core\\interactiveshell.py\", line 2040, in showtraceback\n",
      "    stb = value._render_traceback_()\n",
      "AttributeError: 'TypeError' object has no attribute '_render_traceback_'\n",
      "\n",
      "During handling of the above exception, another exception occurred:\n",
      "\n",
      "Traceback (most recent call last):\n",
      "  File \"C:\\Users\\pcstorm\\AppData\\Roaming\\Python\\Python36\\site-packages\\tensorflow_core\\python\\pywrap_tensorflow.py\", line 58, in <module>\n",
      "    from tensorflow.python.pywrap_tensorflow_internal import *\n",
      "  File \"C:\\Users\\pcstorm\\AppData\\Roaming\\Python\\Python36\\site-packages\\tensorflow_core\\python\\pywrap_tensorflow_internal.py\", line 28, in <module>\n",
      "    _pywrap_tensorflow_internal = swig_import_helper()\n",
      "  File \"C:\\Users\\pcstorm\\AppData\\Roaming\\Python\\Python36\\site-packages\\tensorflow_core\\python\\pywrap_tensorflow_internal.py\", line 24, in swig_import_helper\n",
      "    _mod = imp.load_module('_pywrap_tensorflow_internal', fp, pathname, description)\n",
      "  File \"c:\\users\\pcstorm\\appdata\\local\\programs\\python\\python36\\lib\\imp.py\", line 243, in load_module\n",
      "    return load_dynamic(name, filename, file)\n",
      "  File \"c:\\users\\pcstorm\\appdata\\local\\programs\\python\\python36\\lib\\imp.py\", line 343, in load_dynamic\n",
      "    return _load(spec)\n",
      "ImportError: DLL load failed: The specified module could not be found.\n",
      "\n",
      "\n",
      "Failed to load the native TensorFlow runtime.\n",
      "\n",
      "See https://www.tensorflow.org/install/errors\n",
      "\n",
      "for some common reasons and solutions.  Include the entire stack trace\n",
      "above this error message when asking for help.\n"
     ]
    },
    {
     "ename": "TypeError",
     "evalue": "must be str, not list",
     "output_type": "error",
     "traceback": [
      "\u001b[1;31m---------------------------------------------------------------------------\u001b[0m",
      "\u001b[1;31mImportError\u001b[0m                               Traceback (most recent call last)",
      "\u001b[1;32m~\\AppData\\Roaming\\Python\\Python36\\site-packages\\tensorflow_core\\python\\pywrap_tensorflow.py\u001b[0m in \u001b[0;36m<module>\u001b[1;34m\u001b[0m\n\u001b[0;32m     57\u001b[0m \u001b[1;33m\u001b[0m\u001b[0m\n\u001b[1;32m---> 58\u001b[1;33m   \u001b[1;32mfrom\u001b[0m \u001b[0mtensorflow\u001b[0m\u001b[1;33m.\u001b[0m\u001b[0mpython\u001b[0m\u001b[1;33m.\u001b[0m\u001b[0mpywrap_tensorflow_internal\u001b[0m \u001b[1;32mimport\u001b[0m \u001b[1;33m*\u001b[0m\u001b[1;33m\u001b[0m\u001b[0m\n\u001b[0m\u001b[0;32m     59\u001b[0m   \u001b[1;32mfrom\u001b[0m \u001b[0mtensorflow\u001b[0m\u001b[1;33m.\u001b[0m\u001b[0mpython\u001b[0m\u001b[1;33m.\u001b[0m\u001b[0mpywrap_tensorflow_internal\u001b[0m \u001b[1;32mimport\u001b[0m \u001b[0m__version__\u001b[0m\u001b[1;33m\u001b[0m\u001b[0m\n",
      "\u001b[1;32m~\\AppData\\Roaming\\Python\\Python36\\site-packages\\tensorflow_core\\python\\pywrap_tensorflow_internal.py\u001b[0m in \u001b[0;36m<module>\u001b[1;34m\u001b[0m\n\u001b[0;32m     27\u001b[0m             \u001b[1;32mreturn\u001b[0m \u001b[0m_mod\u001b[0m\u001b[1;33m\u001b[0m\u001b[0m\n\u001b[1;32m---> 28\u001b[1;33m     \u001b[0m_pywrap_tensorflow_internal\u001b[0m \u001b[1;33m=\u001b[0m \u001b[0mswig_import_helper\u001b[0m\u001b[1;33m(\u001b[0m\u001b[1;33m)\u001b[0m\u001b[1;33m\u001b[0m\u001b[0m\n\u001b[0m\u001b[0;32m     29\u001b[0m     \u001b[1;32mdel\u001b[0m \u001b[0mswig_import_helper\u001b[0m\u001b[1;33m\u001b[0m\u001b[0m\n",
      "\u001b[1;32m~\\AppData\\Roaming\\Python\\Python36\\site-packages\\tensorflow_core\\python\\pywrap_tensorflow_internal.py\u001b[0m in \u001b[0;36mswig_import_helper\u001b[1;34m()\u001b[0m\n\u001b[0;32m     23\u001b[0m             \u001b[1;32mtry\u001b[0m\u001b[1;33m:\u001b[0m\u001b[1;33m\u001b[0m\u001b[0m\n\u001b[1;32m---> 24\u001b[1;33m                 \u001b[0m_mod\u001b[0m \u001b[1;33m=\u001b[0m \u001b[0mimp\u001b[0m\u001b[1;33m.\u001b[0m\u001b[0mload_module\u001b[0m\u001b[1;33m(\u001b[0m\u001b[1;34m'_pywrap_tensorflow_internal'\u001b[0m\u001b[1;33m,\u001b[0m \u001b[0mfp\u001b[0m\u001b[1;33m,\u001b[0m \u001b[0mpathname\u001b[0m\u001b[1;33m,\u001b[0m \u001b[0mdescription\u001b[0m\u001b[1;33m)\u001b[0m\u001b[1;33m\u001b[0m\u001b[0m\n\u001b[0m\u001b[0;32m     25\u001b[0m             \u001b[1;32mfinally\u001b[0m\u001b[1;33m:\u001b[0m\u001b[1;33m\u001b[0m\u001b[0m\n",
      "\u001b[1;32mc:\\users\\pcstorm\\appdata\\local\\programs\\python\\python36\\lib\\imp.py\u001b[0m in \u001b[0;36mload_module\u001b[1;34m(name, file, filename, details)\u001b[0m\n\u001b[0;32m    242\u001b[0m         \u001b[1;32melse\u001b[0m\u001b[1;33m:\u001b[0m\u001b[1;33m\u001b[0m\u001b[0m\n\u001b[1;32m--> 243\u001b[1;33m             \u001b[1;32mreturn\u001b[0m \u001b[0mload_dynamic\u001b[0m\u001b[1;33m(\u001b[0m\u001b[0mname\u001b[0m\u001b[1;33m,\u001b[0m \u001b[0mfilename\u001b[0m\u001b[1;33m,\u001b[0m \u001b[0mfile\u001b[0m\u001b[1;33m)\u001b[0m\u001b[1;33m\u001b[0m\u001b[0m\n\u001b[0m\u001b[0;32m    244\u001b[0m     \u001b[1;32melif\u001b[0m \u001b[0mtype_\u001b[0m \u001b[1;33m==\u001b[0m \u001b[0mPKG_DIRECTORY\u001b[0m\u001b[1;33m:\u001b[0m\u001b[1;33m\u001b[0m\u001b[0m\n",
      "\u001b[1;32mc:\\users\\pcstorm\\appdata\\local\\programs\\python\\python36\\lib\\imp.py\u001b[0m in \u001b[0;36mload_dynamic\u001b[1;34m(name, path, file)\u001b[0m\n\u001b[0;32m    342\u001b[0m             name=name, loader=loader, origin=path)\n\u001b[1;32m--> 343\u001b[1;33m         \u001b[1;32mreturn\u001b[0m \u001b[0m_load\u001b[0m\u001b[1;33m(\u001b[0m\u001b[0mspec\u001b[0m\u001b[1;33m)\u001b[0m\u001b[1;33m\u001b[0m\u001b[0m\n\u001b[0m\u001b[0;32m    344\u001b[0m \u001b[1;33m\u001b[0m\u001b[0m\n",
      "\u001b[1;31mImportError\u001b[0m: DLL load failed: The specified module could not be found.",
      "\nDuring handling of the above exception, another exception occurred:\n",
      "\nDuring handling of the above exception, another exception occurred:\n",
      "\u001b[1;31mAttributeError\u001b[0m                            Traceback (most recent call last)",
      "\u001b[1;32mc:\\users\\pcstorm\\appdata\\local\\programs\\python\\python36\\lib\\site-packages\\IPython\\core\\interactiveshell.py\u001b[0m in \u001b[0;36mshowtraceback\u001b[1;34m(self, exc_tuple, filename, tb_offset, exception_only, running_compiled_code)\u001b[0m\n\u001b[0;32m   2039\u001b[0m                         \u001b[1;31m# in the engines. This should return a list of strings.\u001b[0m\u001b[1;33m\u001b[0m\u001b[1;33m\u001b[0m\u001b[0m\n\u001b[1;32m-> 2040\u001b[1;33m                         \u001b[0mstb\u001b[0m \u001b[1;33m=\u001b[0m \u001b[0mvalue\u001b[0m\u001b[1;33m.\u001b[0m\u001b[0m_render_traceback_\u001b[0m\u001b[1;33m(\u001b[0m\u001b[1;33m)\u001b[0m\u001b[1;33m\u001b[0m\u001b[0m\n\u001b[0m\u001b[0;32m   2041\u001b[0m                     \u001b[1;32mexcept\u001b[0m \u001b[0mException\u001b[0m\u001b[1;33m:\u001b[0m\u001b[1;33m\u001b[0m\u001b[0m\n",
      "\u001b[1;31mAttributeError\u001b[0m: 'ImportError' object has no attribute '_render_traceback_'",
      "\nDuring handling of the above exception, another exception occurred:\n",
      "\u001b[1;31mTypeError\u001b[0m                                 Traceback (most recent call last)",
      "\u001b[1;32mc:\\users\\pcstorm\\appdata\\local\\programs\\python\\python36\\lib\\site-packages\\IPython\\core\\interactiveshell.py\u001b[0m in \u001b[0;36mrun_code\u001b[1;34m(self, code_obj, result, async_)\u001b[0m\n\u001b[0;32m   3341\u001b[0m             \u001b[1;32mif\u001b[0m \u001b[0mresult\u001b[0m \u001b[1;32mis\u001b[0m \u001b[1;32mnot\u001b[0m \u001b[1;32mNone\u001b[0m\u001b[1;33m:\u001b[0m\u001b[1;33m\u001b[0m\u001b[0m\n\u001b[0;32m   3342\u001b[0m                 \u001b[0mresult\u001b[0m\u001b[1;33m.\u001b[0m\u001b[0merror_in_exec\u001b[0m \u001b[1;33m=\u001b[0m \u001b[0msys\u001b[0m\u001b[1;33m.\u001b[0m\u001b[0mexc_info\u001b[0m\u001b[1;33m(\u001b[0m\u001b[1;33m)\u001b[0m\u001b[1;33m[\u001b[0m\u001b[1;36m1\u001b[0m\u001b[1;33m]\u001b[0m\u001b[1;33m\u001b[0m\u001b[0m\n\u001b[1;32m-> 3343\u001b[1;33m             \u001b[0mself\u001b[0m\u001b[1;33m.\u001b[0m\u001b[0mshowtraceback\u001b[0m\u001b[1;33m(\u001b[0m\u001b[0mrunning_compiled_code\u001b[0m\u001b[1;33m=\u001b[0m\u001b[1;32mTrue\u001b[0m\u001b[1;33m)\u001b[0m\u001b[1;33m\u001b[0m\u001b[0m\n\u001b[0m\u001b[0;32m   3344\u001b[0m         \u001b[1;32melse\u001b[0m\u001b[1;33m:\u001b[0m\u001b[1;33m\u001b[0m\u001b[0m\n\u001b[0;32m   3345\u001b[0m             \u001b[0moutflag\u001b[0m \u001b[1;33m=\u001b[0m \u001b[1;32mFalse\u001b[0m\u001b[1;33m\u001b[0m\u001b[0m\n",
      "\u001b[1;32mc:\\users\\pcstorm\\appdata\\local\\programs\\python\\python36\\lib\\site-packages\\IPython\\core\\interactiveshell.py\u001b[0m in \u001b[0;36mshowtraceback\u001b[1;34m(self, exc_tuple, filename, tb_offset, exception_only, running_compiled_code)\u001b[0m\n\u001b[0;32m   2041\u001b[0m                     \u001b[1;32mexcept\u001b[0m \u001b[0mException\u001b[0m\u001b[1;33m:\u001b[0m\u001b[1;33m\u001b[0m\u001b[0m\n\u001b[0;32m   2042\u001b[0m                         stb = self.InteractiveTB.structured_traceback(etype,\n\u001b[1;32m-> 2043\u001b[1;33m                                             value, tb, tb_offset=tb_offset)\n\u001b[0m\u001b[0;32m   2044\u001b[0m \u001b[1;33m\u001b[0m\u001b[0m\n\u001b[0;32m   2045\u001b[0m                     \u001b[0mself\u001b[0m\u001b[1;33m.\u001b[0m\u001b[0m_showtraceback\u001b[0m\u001b[1;33m(\u001b[0m\u001b[0metype\u001b[0m\u001b[1;33m,\u001b[0m \u001b[0mvalue\u001b[0m\u001b[1;33m,\u001b[0m \u001b[0mstb\u001b[0m\u001b[1;33m)\u001b[0m\u001b[1;33m\u001b[0m\u001b[0m\n",
      "\u001b[1;32mc:\\users\\pcstorm\\appdata\\local\\programs\\python\\python36\\lib\\site-packages\\IPython\\core\\ultratb.py\u001b[0m in \u001b[0;36mstructured_traceback\u001b[1;34m(self, etype, value, tb, tb_offset, number_of_lines_of_context)\u001b[0m\n\u001b[0;32m   1383\u001b[0m         \u001b[0mself\u001b[0m\u001b[1;33m.\u001b[0m\u001b[0mtb\u001b[0m \u001b[1;33m=\u001b[0m \u001b[0mtb\u001b[0m\u001b[1;33m\u001b[0m\u001b[0m\n\u001b[0;32m   1384\u001b[0m         return FormattedTB.structured_traceback(\n\u001b[1;32m-> 1385\u001b[1;33m             self, etype, value, tb, tb_offset, number_of_lines_of_context)\n\u001b[0m\u001b[0;32m   1386\u001b[0m \u001b[1;33m\u001b[0m\u001b[0m\n\u001b[0;32m   1387\u001b[0m \u001b[1;33m\u001b[0m\u001b[0m\n",
      "\u001b[1;32mc:\\users\\pcstorm\\appdata\\local\\programs\\python\\python36\\lib\\site-packages\\IPython\\core\\ultratb.py\u001b[0m in \u001b[0;36mstructured_traceback\u001b[1;34m(self, etype, value, tb, tb_offset, number_of_lines_of_context)\u001b[0m\n\u001b[0;32m   1286\u001b[0m             \u001b[1;31m# Verbose modes need a full traceback\u001b[0m\u001b[1;33m\u001b[0m\u001b[1;33m\u001b[0m\u001b[0m\n\u001b[0;32m   1287\u001b[0m             return VerboseTB.structured_traceback(\n\u001b[1;32m-> 1288\u001b[1;33m                 \u001b[0mself\u001b[0m\u001b[1;33m,\u001b[0m \u001b[0metype\u001b[0m\u001b[1;33m,\u001b[0m \u001b[0mvalue\u001b[0m\u001b[1;33m,\u001b[0m \u001b[0mtb\u001b[0m\u001b[1;33m,\u001b[0m \u001b[0mtb_offset\u001b[0m\u001b[1;33m,\u001b[0m \u001b[0mnumber_of_lines_of_context\u001b[0m\u001b[1;33m\u001b[0m\u001b[0m\n\u001b[0m\u001b[0;32m   1289\u001b[0m             )\n\u001b[0;32m   1290\u001b[0m         \u001b[1;32melif\u001b[0m \u001b[0mmode\u001b[0m \u001b[1;33m==\u001b[0m \u001b[1;34m'Minimal'\u001b[0m\u001b[1;33m:\u001b[0m\u001b[1;33m\u001b[0m\u001b[0m\n",
      "\u001b[1;32mc:\\users\\pcstorm\\appdata\\local\\programs\\python\\python36\\lib\\site-packages\\IPython\\core\\ultratb.py\u001b[0m in \u001b[0;36mstructured_traceback\u001b[1;34m(self, etype, evalue, etb, tb_offset, number_of_lines_of_context)\u001b[0m\n\u001b[0;32m   1148\u001b[0m         \u001b[0mexception\u001b[0m \u001b[1;33m=\u001b[0m \u001b[0mself\u001b[0m\u001b[1;33m.\u001b[0m\u001b[0mget_parts_of_chained_exception\u001b[0m\u001b[1;33m(\u001b[0m\u001b[0mevalue\u001b[0m\u001b[1;33m)\u001b[0m\u001b[1;33m\u001b[0m\u001b[0m\n\u001b[0;32m   1149\u001b[0m         \u001b[1;32mif\u001b[0m \u001b[0mexception\u001b[0m\u001b[1;33m:\u001b[0m\u001b[1;33m\u001b[0m\u001b[0m\n\u001b[1;32m-> 1150\u001b[1;33m             \u001b[0mformatted_exceptions\u001b[0m \u001b[1;33m+=\u001b[0m \u001b[0mself\u001b[0m\u001b[1;33m.\u001b[0m\u001b[0mprepare_chained_exception_message\u001b[0m\u001b[1;33m(\u001b[0m\u001b[0mevalue\u001b[0m\u001b[1;33m.\u001b[0m\u001b[0m__cause__\u001b[0m\u001b[1;33m)\u001b[0m\u001b[1;33m\u001b[0m\u001b[0m\n\u001b[0m\u001b[0;32m   1151\u001b[0m             \u001b[0metype\u001b[0m\u001b[1;33m,\u001b[0m \u001b[0mevalue\u001b[0m\u001b[1;33m,\u001b[0m \u001b[0metb\u001b[0m \u001b[1;33m=\u001b[0m \u001b[0mexception\u001b[0m\u001b[1;33m\u001b[0m\u001b[0m\n\u001b[0;32m   1152\u001b[0m         \u001b[1;32melse\u001b[0m\u001b[1;33m:\u001b[0m\u001b[1;33m\u001b[0m\u001b[0m\n",
      "\u001b[1;31mTypeError\u001b[0m: must be str, not list"
     ]
    }
   ],
   "source": [
    "from imageai.Detection import ObjectDetection\n",
    "import os"
   ]
  },
  {
   "cell_type": "code",
   "execution_count": null,
   "metadata": {},
   "outputs": [],
   "source": [
    "detector = ObjectDetection()"
   ]
  },
  {
   "cell_type": "code",
   "execution_count": null,
   "metadata": {},
   "outputs": [],
   "source": [
    "model_path = \"models/yolo-tiny.h5\"\n",
    "input_path = \"image/test1.jpg\"\n",
    "output_path = \"image/output1.jpg\""
   ]
  },
  {
   "cell_type": "code",
   "execution_count": null,
   "metadata": {},
   "outputs": [],
   "source": [
    "detector.setModelTypeAsTinyYOLOv3()\n",
    "detector.setModelPath(model_path)\n",
    "detector.loadModel(detection_speed=\"fast\")\n",
    "detection = detector.detectObjectsFromImage(input_image=input_path, output_image_path=output_path)"
   ]
  },
  {
   "cell_type": "code",
   "execution_count": null,
   "metadata": {},
   "outputs": [],
   "source": [
    "custom_objects = detector.CustomObjects(car=True)"
   ]
  },
  {
   "cell_type": "code",
   "execution_count": null,
   "metadata": {},
   "outputs": [],
   "source": [
    "detections = detector.detectCustomObjectsFromImage(custom_objects=custom_objects, input_image=os.path.join(\"image/test1.jpg\"), output_image_path=os.path.join(\"image/output1.jpg\"), minimum_percentage_probability=30)\n",
    "\n",
    "for eachObject in detections:\n",
    "    print(eachObject[\"name\"] , \" : \", eachObject[\"percentage_probability\"], \" : \", eachObject[\"box_points\"] )\n",
    "    print(\"--------------------------------\")"
   ]
  },
  {
   "cell_type": "code",
   "execution_count": null,
   "metadata": {},
   "outputs": [],
   "source": [
    "from matplotlib.pyplot import imshow\n",
    "import numpy as np\n",
    "from PIL import Image\n",
    "\n",
    "%matplotlib inline\n",
    "pil_im = Image.open('image/output1.jpg', 'r')\n",
    "imshow(np.asarray(pil_im))"
   ]
  },
  {
   "cell_type": "code",
   "execution_count": null,
   "metadata": {},
   "outputs": [],
   "source": [
    "#plotting a sample detected car\n",
    "image = Image.open('image/output1.jpg')\n",
    "box = (520, 451, 742, 675)\n",
    "cropped_image = image.crop(box).resize((100, 100))\n",
    "imshow(cropped_image)"
   ]
  },
  {
   "cell_type": "code",
   "execution_count": null,
   "metadata": {},
   "outputs": [],
   "source": [
    "from __future__ import print_function\n",
    "import keras\n",
    "from keras.datasets import mnist\n",
    "from keras.models import Sequential\n",
    "from keras.layers import Dense, Dropout, Flatten\n",
    "from keras.layers import Conv2D, MaxPooling2D\n",
    "from keras import backend as K"
   ]
  },
  {
   "cell_type": "code",
   "execution_count": null,
   "metadata": {},
   "outputs": [],
   "source": [
    "batch_size = 128\n",
    "num_classes = 196\n",
    "epochs = 196\n",
    "\n",
    "# input image dimensions\n",
    "img_rows, img_cols = 400, 400\n",
    "\n",
    "# the data, split between train and test sets\n",
    "\n",
    "# convert class vectors to binary class matrices\n",
    "y_train = keras.utils.to_categorical(y_train, num_classes)\n",
    "\n",
    "model = Sequential()\n",
    "model.add(Conv2D(32, kernel_size=(3, 3),\n",
    "                 activation='relu',\n",
    "                 input_shape=(64, 64, 3)))\n",
    "model.add(Conv2D(64, (3, 3), activation='relu'))\n",
    "model.add(MaxPooling2D(pool_size=(2, 2)))\n",
    "model.add(Dropout(0.25))\n",
    "model.add(Flatten())\n",
    "model.add(Dense(128, activation='relu'))\n",
    "model.add(Dropout(0.5))\n",
    "model.add(Dense(num_classes, activation='softmax'))\n",
    "\n",
    "model.compile(loss=keras.losses.categorical_crossentropy,\n",
    "              optimizer=keras.optimizers.Adadelta(),\n",
    "              metrics=['accuracy'])\n",
    "\n",
    "model.fit(x_train, y_train,\n",
    "          batch_size=batch_size,\n",
    "          epochs=epochs,\n",
    "          verbose=1,\n",
    "          validation_data=(x_test, y_test))\n"
   ]
  },
  {
   "cell_type": "code",
   "execution_count": null,
   "metadata": {},
   "outputs": [],
   "source": [
    "img_train = []\n",
    "import numpy as np\n",
    "from keras.preprocessing import image"
   ]
  },
  {
   "cell_type": "code",
   "execution_count": null,
   "metadata": {},
   "outputs": [],
   "source": [
    "import os\n",
    "trainingDir = \"C:/Users/pcstorm/AppData/Local/Programs/Python/Python36/JupyterNotebookFiles/term-7/DL/Final-Project/DeepFinalProject/image/cars_train/\"\n",
    "for filename in os.listdir(trainingDir):\n",
    "    test_image = image.load_img(trainingDir+filename, target_size = (64, 64))\n",
    "    test_image = image.img_to_array(test_image)\n",
    "    test_image = np.expand_dims(test_image, axis = 0)\n",
    "    img_train.append(test_image)"
   ]
  },
  {
   "cell_type": "code",
   "execution_count": null,
   "metadata": {},
   "outputs": [],
   "source": [
    "target_train = []\n",
    "numOfLines = 0\n",
    "thefilepath = \"C:/Users/pcstorm/AppData/Local/Programs/Python/Python36/JupyterNotebookFiles/term-7/DL/Final-Project/DeepFinalProject/image/devkit/train_perfect_preds.txt\"\n",
    "numOfLines = len(open(thefilepath).readlines(  ))\n",
    "\n",
    "f = open(thefilepath, \"r\")\n",
    "for i in range(numOfLines):\n",
    "    target_train.append(int(f.readline()[:-1]))"
   ]
  },
  {
   "cell_type": "code",
   "execution_count": null,
   "metadata": {
    "scrolled": false
   },
   "outputs": [],
   "source": [
    "target_train[0:10]"
   ]
  },
  {
   "cell_type": "code",
   "execution_count": null,
   "metadata": {},
   "outputs": [],
   "source": [
    "np.shape(img_train[0])"
   ]
  },
  {
   "cell_type": "code",
   "execution_count": null,
   "metadata": {},
   "outputs": [],
   "source": [
    "img_test = []\n",
    "import os\n",
    "trainingDir = \"C:/Users/pcstorm/AppData/Local/Programs/Python/Python36/JupyterNotebookFiles/term-7/DL/Final-Project/DeepFinalProject/image/cars_test/\"\n",
    "for filename in os.listdir(trainingDir):\n",
    "    test_image = image.load_img(trainingDir+filename, target_size = (64, 64))\n",
    "    test_image = image.img_to_array(test_image)\n",
    "    test_image = np.expand_dims(test_image, axis = 0)\n",
    "    img_test.append(test_image)"
   ]
  },
  {
   "cell_type": "code",
   "execution_count": null,
   "metadata": {},
   "outputs": [],
   "source": [
    "batch_size = 128\n",
    "num_classes = 196\n",
    "epochs = 196\n",
    "model = Sequential()\n",
    "model.add(Conv2D(32, kernel_size=(3, 3),\n",
    "                 activation='relu',\n",
    "                 input_shape=(64, 64, 3)))\n",
    "model.add(Conv2D(64, (3, 3), activation='relu'))\n",
    "model.add(MaxPooling2D(pool_size=(2, 2)))\n",
    "model.add(Dropout(0.25))\n",
    "model.add(Flatten())\n",
    "model.add(Dense(32, activation='relu'))\n",
    "model.add(Dropout(0.5))\n",
    "model.add(Dense(num_classes, activation='softmax'))\n",
    "\n",
    "model.compile(loss=keras.losses.categorical_crossentropy,\n",
    "              optimizer=keras.optimizers.Adadelta(),\n",
    "              metrics=['accuracy'])"
   ]
  },
  {
   "cell_type": "code",
   "execution_count": null,
   "metadata": {},
   "outputs": [],
   "source": [
    "img_train = np.array(img_train)"
   ]
  },
  {
   "cell_type": "code",
   "execution_count": null,
   "metadata": {},
   "outputs": [],
   "source": [
    "img_train.resize((8144,64, 64, 3))"
   ]
  },
  {
   "cell_type": "code",
   "execution_count": null,
   "metadata": {},
   "outputs": [],
   "source": [
    "target_train = keras.utils.to_categorical( target_train, num_classes= num_classes)"
   ]
  },
  {
   "cell_type": "code",
   "execution_count": null,
   "metadata": {},
   "outputs": [],
   "source": [
    "model.fit(img_train, target_train,\n",
    "          batch_size=batch_size,\n",
    "          epochs=epochs)"
   ]
  },
  {
   "cell_type": "code",
   "execution_count": null,
   "metadata": {},
   "outputs": [],
   "source": [
    "import numpy as np\n",
    "from keras.models import Sequential\n",
    "from keras.layers import Dense, Dropout, Activation, Flatten\n",
    "from keras.layers.convolutional import Conv2D\n",
    "from keras.layers.pooling import MaxPooling2D\n",
    "from keras.layers.merge import concatenate\n",
    "from keras.optimizers import SGD\n",
    "from keras.callbacks import ModelCheckpoint\n",
    "from keras.layers import Input\n",
    "from keras.models import Model\n",
    "\n",
    "visible1 = Input(shape=(64,64,3))\n",
    "conv11 = Conv2D(32, kernel_size=4, activation='relu')(visible1)\n",
    "pool11 = MaxPooling2D(pool_size=(2, 2))(conv11)\n",
    "conv12 = Conv2D(16, kernel_size=4, activation='relu')(pool11)\n",
    "pool12 = MaxPooling2D(pool_size=(2, 2))(conv12)\n",
    "flat1 = Flatten()(pool12)\n",
    "\n",
    "hidden1 = Dense(10, activation='relu')(flat1)\n",
    "hidden2 = Dense(10, activation='relu')(hidden1)\n",
    "output1 = Dense(196, activation='sigmoid')(hidden2)\n",
    "model = Model(inputs=[visible1], outputs=[output1])\n",
    "model.compile(optimizer='adam', loss='binary_crossentropy',metrics=['accuracy'])"
   ]
  },
  {
   "cell_type": "code",
   "execution_count": null,
   "metadata": {},
   "outputs": [],
   "source": [
    "model.fit(img_train, target_train,\n",
    "          batch_size=batch_size,\n",
    "          epochs=epochs)"
   ]
  },
  {
   "cell_type": "code",
   "execution_count": null,
   "metadata": {},
   "outputs": [],
   "source": [
    "model_json = model.to_json()\n",
    "with open(\"model.json\", \"w\") as json_file:\n",
    "    json_file.write(model_json)\n",
    "model.save_weights(\"models/carTypeDetectionModel.h5\")"
   ]
  },
  {
   "cell_type": "code",
   "execution_count": null,
   "metadata": {},
   "outputs": [],
   "source": [
    "for i in range(len(img_test)):\n",
    "    "
   ]
  },
  {
   "cell_type": "code",
   "execution_count": null,
   "metadata": {},
   "outputs": [],
   "source": []
  },
  {
   "cell_type": "code",
   "execution_count": null,
   "metadata": {},
   "outputs": [],
   "source": []
  },
  {
   "cell_type": "code",
   "execution_count": null,
   "metadata": {},
   "outputs": [],
   "source": []
  }
 ],
 "metadata": {
  "kernelspec": {
   "display_name": "Python 3",
   "language": "python",
   "name": "python3"
  },
  "language_info": {
   "codemirror_mode": {
    "name": "ipython",
    "version": 3
   },
   "file_extension": ".py",
   "mimetype": "text/x-python",
   "name": "python",
   "nbconvert_exporter": "python",
   "pygments_lexer": "ipython3",
   "version": "3.6.5"
  }
 },
 "nbformat": 4,
 "nbformat_minor": 2
}
